Workbook

Sheet Datos Limpios
A1: Superviviente | B1: Pclase | C1: Sexo | D1: Edad | E1: HermanosConyuges | F1: PadresHijosAbordo | G1: Tarifa | H1: Embarque
A2: 0 | B2: 3 | C2: hombre | D2: 22 | E2: 1 | F2: 0 | G2: 7.25 | H2: S
A3: 1 | B3: 1 | C3: mujer | D3: 38 | E3: 1 | F3: 0 | G3: 71.2833 | H3: C
A4: 1 | B4: 3 | C4: mujer | D4: 26 | E4: 0 | F4: 0 | G4: 7.925 | H4: S
A5: 1 | B5: 1 | C5: mujer | D5: 35 | E5: 1 | F5: 0 | G5: 53.1 | H5: S
A6: 0 | B6: 3 | C6: hombre | D6: 35 | E6: 0 | F6: 0 | G6: 8.05 | H6: S
A7: 0 | B7: 3 | C7: hombre | D7: 29.7 | E7: 0 | F7: 0 | G7: 8.4583 | H7: Q
A8: 0 | B8: 1 | C8: hombre | D8: 54 | E8: 0 | F8: 0 | G8: 51.8625 | H8: S
A9: 0 | B9: 3 | C9: hombre | D9: 2 | E9: 3 | F9: 1 | G9: 21.075 | H9: S
A10: 1 | B10: 3 | C10: mujer | D10: 27 | E10: 0 | F10: 2 | G10: 11.1333 | H10: S
A11: 1 | B11: 2 | C11: mujer | D11: 14 | E11: 1 | F11: 0 | G11: 30.0708 | H11: C
A12: 1 | B12: 3 | C12: mujer | D12: 4 | E12: 1 | F12: 1 | G12: 16.7 | H12: S
A13: 1 | B13: 1 | C13: mujer | D13: 58 | E13: 0 | F13: 0 | G13: 26.55 | H13: S
... A890: 0 | B890: 3 | C890: hombre | D890: 32 | E890: 0 | F890: 0 | G890: 7.75 | H890: Q

Sheet Tablas Cualitativas
A1: Sobrevivientes | C1: Variable Categórica | E1: POR FAVOR IR MAS A LA DERECHA PARA VER LAS OTRAS 3 VARIABLES | P1: Pclase | R1: Variable Categórica | AE1: Sexo | AG1: Variable Categórica | AV1: Embarque | AX1: Variable Categórica
A2: 0 | C2: a) Distribución de Frecuencias de Supervivencia en el Titanic | P2: 1 | R2: b) Distribución de Frecuencias por clases en el Titanic | AE2: mujer | AG2: c) Distribución de Frecuencias por el sexo en el Titanic | AV2: C | AX2: d) Distribución de Frecuencias de los embarques al Titanic
A3: 0 | P3: 1 | W3: F.acum. Menor que | Z3: F.acum Mayor que | AE3: mujer | AV3: C
A4: 0 | C4: Categoría | D4: Valor | E4: fi | F4: fr | G4: % | P4: 1 | R4: Categoría | S4: Valor | T4: fi | U4: fr | V4: % | W4: Fi(-) | X4: Fr(-) | Y4: % (-) | Z4: Fi(+) | AA4: Fr(+) | AB4: %(+) | AE4: mujer | AG4: Categoría | AH4: Valor | AI4: fi | AJ4: fr | AK4: % | AV4: C | AX4: Puerto | AY4: Valor | AZ4: fi | BA4: fr | BB4: %
A5: 0 | C5: No sobrevivientes | D5: 0 | E5: {=FREQUENCY(A2:A890, D5:D6)} -> 549 | F5: =E5/$E$7 -> 0.61754781 | G5: =F5 -> 0.61754781 | P5: 1 | R5: Primera clase | S5: 1 | T5: {=FREQUENCY(P2:P890, S5:S7)} -> 214 | U5: =T5/$T$8 -> 0.24071991 | V5: =U5 -> 0.24071991 | W5: =T5 -> 214 | X5: =U5 -> 0.24071991 | Y5: =V5 -> 0.24071991 | Z5: {=T8:V8} -> 889 | AA5: 1 | AB5: 1 | AE5: mujer | AG5: Damas | AH5: mujer | AI5: =COUNTIF(AE2:AE890, "mujer") -> 312 | AJ5: =AI5/$E$7 -> 0.35095613 | AK5: =AJ5 -> 0.35095613 | AV5: C | AX5: Queenstown | AY5: Q | AZ5: =COUNTIF(AV2:AV890, "Q") -> 77 | BA5: =AZ5/$AZ$8 -> 0.086614173 | BB5: =BA5 -> 0.086614173
A6: 0 | C6: Sobrevivientes | D6: 1 | E6: 340 | F6: =E6/$E$7 -> 0.38245219 | G6: =F6 -> 0.38245219 | P6: 1 | R6: Segunda clase | S6: 2 | T6: 184 | U6: =T6/$T$8 -> 0.20697413 | V6: =U6 -> 0.20697413 | W6: =W5+T6 -> 398 | X6: =X5+U6 -> 0.44769404 | Y6: =Y5+V6 -> 0.44769404 | Z6: {=_xlfn.ANCHORARRAY(Z5)-T5:V5} -> 675 | AA6: 0.75928009 | AB6: 0.75928009 | AE6: mujer | AG6: Varones | AH6: hombre | AI6: =COUNTIF(AE2:AE890, "hombre") -> 577 | AJ6: =AI6/$E$7 -> 0.64904387 | AK6: =AJ6 -> 0.64904387 | AV6: C | AX6: Cherbourg | AY6: C | AZ6: =COUNTIF(AV2:AV890, "C") -> 168 | BA6: =AZ6/$AZ$8 -> 0.18897638 | BB6: =BA6 -> 0.18897638
A7: 0 | C7: Total | E7: =SUM(E5:E6) -> 889 | F7: =SUM(F5:F6) -> 1 | G7: =SUM(G5:G6) -> 1 | P7: 1 | R7: Tercera clase | S7: 3 | T7: 491 | U7: =T7/$T$8 -> 0.55230596 | V7: =U7 -> 0.55230596 | W7: =W6+T7 -> 889 | X7: =X6+U7 -> 1 | Y7: =Y6+V7 -> 1 | Z7: {=_xlfn.ANCHORARRAY(Z6)-T6:V6} -> 491 | AA7: 0.55230596 | AB7: 0.55230596 | AE7: mujer | AG7: Total | AI7: =SUM(AI5:AI6) -> 889 | AJ7: =SUM(AJ5:AJ6) -> 1 | AK7: =SUM(AK5:AK6) -> 1 | AV7: C | AX7: Southampton | AY7: S | AZ7: =COUNTIF(AV2:AV890, "S") -> 644 | BA7: =AZ7/$AZ$8 -> 0.72440945 | BB7: =BA7 -> 0.72440945
A8: 0 | P8: 1 | R8: Total | T8: =SUM(T5:T7) -> 889 | U8: =SUM(U5:U7) -> 1 | V8: =SUM(V5:V7) -> 1 | AE8: mujer | AV8: C | AX8: Total | AZ8: =SUM(AZ5:AZ7) -> 889 | BA8: =SUM(BA5:BA7) -> 1 | BB8: =SUM(BB5:BB7) -> 1
A9: 0 | C9: INTERPRETACION | P9: 1 | AE9: mujer | AG9: INTERPRETACION | AV9: C
A10: 0 | C10: Esta tabla muestra la tasa de supervivencia del Titanic con una mortalidad muy superior a la supervivencia. | P10: 1 | R10: INTERPRETACION | AE10: mujer | AG10: Los datos muestran una masculinización marcada del pasaje. | AV10: C | AX10: INTERPRETACION
A11: 0 | C11: Solo el 38,25% de las personas a bordo sobrevivieron, mientras que el 61,75% (549 personas) fallecieron. | P11: 1 | R11: La tabla revela una inequidad estructural en el pasaje del Titanic. | AE11: mujer | AG11: Los varones representan el 64,90% (577 personas) contra solo 35,10% de damas (312 personas). | AV11: C | AX11: Los datos muestran una concentración absoluta en Southampton
A12: 0 | C12: La diferencia absoluta de 209 personas indica que por cada superviviente hubo aproximadamente 1,6 víctimas. | P12: 1 | R12: La Tercera Clase representa el 55,23% (491 pasajeros) del total, más del doble que la Primera Clase (24,07%). | AE12: mujer | AG12: Esta diferencia de 265 personas refleja las normas sociales de 1912, donde los hombres viajaban más por trabajo o migración, | AV12: C | AX12: El 72,44% de los pasajeros (644 personas) embarcó en este puerto inglés, seguido muy lejos por Cherbourg (18,90%, 168 personas) y finalmente Queenstown (8,66%, 77 personas)
A13: 0 | C13: La catástrofe fue extremadamente severa, con casi 2 de cada 3 personas perdiendo la vida. | P13: 1 | R13: La Segunda Clase es el grupo más pequeño con apenas el 20,70%. | AE13: mujer | AG13: mientras las mujeres lo hacían generalmente acompañadas. | AV13: C | AX13: Esta distribución refleja la ruta oficial del Titanic: Southampton → Cherbourg → Queenstown, donde el primer puerto capturó la mayoría del pasaje principalmente británico.
A14: 0 | P14: 1 | R14: La distribución refleja la pirámide socioeconómica de 1912. | AE14: mujer | AG14: Hay 1,85 hombres por cada mujer a bordo. | AV14: C | AX14: Relevancia para análisis: El puerto está correlacionado con clase social y nacionalidad
A15: 0 | C15: REPRESENTACION VISUAL | P15: 1 | AE15: mujer | AV15: C
A16: 0 | C16: Torta o gráfico circular | P16: 1 | R16: REPRESENTACION VISUAL | AE16: mujer | AG16: REPRESENTACION VISUAL | AV16: C | AX16: REPRESENTACION VISUAL
A17: 0 | C17: Grafico N°1 Distribución porcentual de supervivientes y víctimas del Titanic | P17: 1 | R17: Torta o gráfico circular | AE17: mujer | AG17: Torta o gráfico circular | AV17: C | AX17: Torta o gráfico circular
A18: 0 | P18: 1 | R18: Grafico N°1 Proporción porcentual de pasajeros por clase en el Titanic | AE18: mujer | AG18: Grafico N°1 Distribución porcentual de supervivientes y víctimas del Titanic | AV18: C | AX18: Grafico N°1 Proporción porcentual de pasajeros por puerto de embarque
A19: 0 | P19: 1 | AE19: mujer | AV19: C
A20: 0 | P20: 1 | AE20: mujer | AV20: C
A21: 0 | P21: 1 | AE21: mujer | AV21: C
A22: 0 | P22: 1 | AE22: mujer | AV22: C
A23: 0 | P23: 1 | AE23: mujer | AV23: C
A24: 0 | P24: 1 | AE24: mujer | AV24: C
A25: 0 | P25: 1 | AE25: mujer | AV25: C
A26: 0 | P26: 1 | AE26: mujer | AV26: C
A27: 0 | P27: 1 | AE27: mujer | AV27: C
A28: 0 | P28: 1 | AE28: mujer | AV28: C
A29: 0 | P29: 1 | AE29: mujer | AV29: C
A30: 0 | C30: Fuente: Dataset público de Kaggle "Titanic - Machine Learning from Disaster" | P30: 1 | AE30: mujer | AV30: C
A31: 0 | P31: 1 | R31: Fuente: Dataset público de Kaggle "Titanic - Machine Learning from Disaster" | AE31: mujer | AG31: Fuente: Dataset público de Kaggle "Titanic - Machine Learning from Disaster" | AV31: C | AX31: Fuente: Dataset público de Kaggle "Titanic - Machine Learning from Disaster"
A32: 0 | P32: 1 | AE32: mujer | AV32: C
A33: 0 | C33: REPRESENTACION VISUAL | P33: 1 | AE33: mujer | AV33: C
A34: 0 | C34: Histograma o gráfico de barras | P34: 1 | R34: REPRESENTACION VISUAL | AE34: mujer | AG34: REPRESENTACION VISUAL | AV34: C | AX34: REPRESENTACION VISUAL
A35: 0 | C35: Grafico N°2 Comparativa absoluta de supervivientes y víctimas del Titanic | P35: 1 | R35: Histograma o gráfico de barras | AE35: mujer | AG35: Histograma o gráfico de barras | AV35: C | AX35: Histograma o gráfico de barras
A36: 0 | P36: 1 | R36: Grafico N°2 Distribución de pasajeros del Titanic por clase social | AE36: mujer | AG36: Grafico N°2 Comparativa absoluta de supervivientes y víctimas del Titanic | AV36: C | AX36: Grafico N°2 Concentración de pasajeros del Titanic por puerto de embarque
A37: 0 | P37: 1 | AE37: mujer | AV37: C
A38: 0 | P38: 1 | AE38: mujer | AV38: C
A39: 0 | P39: 1 | AE39: mujer | AV39: C
A40: 0 | P40: 1 | AE40: mujer | AV40: C
...

Sheet Tablas Cruzadas
B1: SEXO X SUPERVIVENCIA
B3: Tabla de contingencia
C4: No (0) | D4: Si (1) | E4: Total
B5: hombre | C5: 468 | D5: 109 | E5: 577
B6: mujer | C6: 81 | D6: 231 | E6: 312
B7: Total | C7: 549 | D7: 340 | E7: 889
B10: Tabla de probabilidad
C11: No (0) | D11: Si (1) | E11: Total
B12: hombre | C12: 0.5264342 | D12: 0.12260967 | E12: 0.64904387
B13: mujer | C13: 0.091113611 | D13: 0.25984252 | E13: 0.35095613
B14: Total | C14: 0.61754781 | D14: 0.38245219 | E14: 1
B16: a) Probabilidades Marginales: | E16: Significado
B17: P(Hombre) | C17: =GETPIVOTDATA("[Measures].[Count of Superviviente]",$B$10,"[Range].[Sexo]","[Range].[Sexo].&[hombre]") -> 0.64904387 | D17: =C17 -> 0.64904387 | E17: (probabilidad previa de ser hombre)
B18: P(Mujer) | C18: =GETPIVOTDATA("[Measures].[Count of Superviviente]",$B$10,"[Range].[Sexo]","[Range].[Sexo].&[mujer]") -> 0.35095613 | D18: =C18 -> 0.35095613 | E18: (probabilidad previa de ser mujer)
B19: P(Sobrevivir) | C19: =GETPIVOTDATA("[Measures].[Count of Superviviente]",$B$10,"[Range].[Superviviente]","[Range].[Superviviente].&[1]") -> 0.38245219 | D19: =C19 -> 0.38245219 | E19: (probabilidad marginal de supervivencia)
B20: P(No sobrevivir) | C20: =GETPIVOTDATA("[Measures].[Count of Superviviente]",$B$10,"[Range].[Superviviente]","[Range].[Superviviente].&[0]") -> 0.61754781 | D20: =C20 -> 0.61754781 | E20: (probabilidad marginal de no supervivencia)
B22: b) Probabilidades Conjuntas: | E22: Significado
B23: P(H ∩ No) | C23: =GETPIVOTDATA("[Measures].[Count of Superviviente]",$B$10,"[Range].[Sexo]","[Range].[Sexo].&[hombre]","[Range].[Superviviente]","[Range].[Superviviente].&[0]") -> 0.5264342 | D23: =C23 -> 0.5264342 | E23: (probabilidad de que al azar sea hombre y fallezca)
B24: P(H ∩ Si) | C24: =GETPIVOTDATA("[Measures].[Count of Superviviente]",$B$10,"[Range].[Sexo]","[Range].[Sexo].&[hombre]","[Range].[Superviviente]","[Range].[Superviviente].&[1]") -> 0.12260967 | D24: =C24 -> 0.12260967 | E24: (probabilidad de que al azar sea hombre y fallezca)
B25: P(M ∩ No) | C25: =GETPIVOTDATA("[Measures].[Count of Superviviente]",$B$10,"[Range].[Sexo]","[Range].[Sexo].&[mujer]","[Range].[Superviviente]","[Range].[Superviviente].&[0]") -> 0.091113611 | D25: =C25 -> 0.091113611 | E25: (probabilidad de que al azar sea mujer y fallezca)
B26: P(M ∩ Si) | C26: =GETPIVOTDATA("[Measures].[Count of Superviviente]",$B$10,"[Range].[Sexo]","[Range].[Sexo].&[mujer]","[Range].[Superviviente]","[Range].[Superviviente].&[1]") -> 0.25984252 | D26: =C26 -> 0.25984252 | E26: (probabilidad de que al azar sea mujer Y sobreviva)
B28: c) Probabilidades Condicionales Clave: | E28: Significado
B29: P(Sobrevivir | Mujer) | C29: =GETPIVOTDATA("[Measures].[Count of Superviviente]",$B$10,"[Range].[Sexo]","[Range].[Sexo].&[mujer]","[Range].[Superviviente]","[Range].[Superviviente].&[1]")/GETPIVOTDATA("[Measures].[Count of Superviviente]",$B$10,"[Range].[Sexo]","[Range].[Sexo].&[mujer]") -> 0.74038462 | D29: =C29 -> 0.74038462 | E29: (Interpretación: Una mujer tenía 74% de probabilidad de sobrevivir.)
B30: P(Sobrevivir | Hombre) | C30: =GETPIVOTDATA("[Measures].[Count of Superviviente]",$B$10,"[Range].[Sexo]","[Range].[Sexo].&[hombre]","[Range].[Superviviente]","[Range].[Superviviente].&[1]")/GETPIVOTDATA("[Measures].[Count of Superviviente]",$B$10,"[Range].[Sexo]","[Range].[Sexo].&[hombre]") -> 0.18890815 | D30: =C30 -> 0.18890815 | E30: (Interpretación: Un hombre tenía solo 19% de probabilidad de sobrevivir.)
B32: HALLAZGOS ESTADÍSTICOS Y PROBABILÍSTICOS
B33: 1. Efecto Sexo: La probabilidad de supervivencia entre mujeres es cuatro veces superior a la de hombres (74% vs 19%), confirmando que el sexo fue el predictor más fuerte.
B34: 2. Distribución Asimétrica: El 52.6% de la población total (hombres fallecidos) concentra el mayor número de víctimas, mientras que las mujeres sobrevivientes representan el 25.98% del total, superando ampliamente su proporción poblacional (35.1%).
B35: 3. Cumplimiento de Objetivos: Esta tabla satisface el OE1 ("Establecer distribución de supervivencia según sexo") y proporciona base para el OE4 al cruzarse con clase y embarque en tablas adicionales.
B36: Conclusión Probabilística: El sexo no solo es un factor diferenciador, sino que cambia radicalmente la probabilidad a posteriori de supervivencia, evidenciando que las políticas de evacuación no fueron neutrales y afectaron desproporcionadamente a hombres de todas las clases.
B39: CLASE SOCIAL X SUPERVIVENCIA
B41: Tabla de contingencia
C42: No (0) | D42: Si (1) | E42: Total
B43: 1 | C43: 80 | D43: 134 | E43: 214
B44: 2 | C44: 97 | D44: 87 | E44: 184
B45: 3 | C45: 372 | D45: 119 | E45: 491
B46: Total | C46: 549 | D46: 340 | E46: 889
B49: Tabla de probabilidad
C50: No (0) | D50: Si (1) | E50: Total
B51: 1ra Clase | C51: 0.089988751 | D51: 0.15073116 | E51: 0.24071991
B52: 2da clase | C52: 0.10911136 | D52: 0.097862767 | E52: 0.20697413
...

Sheet Estadísticos Descriptivos
A1: Edad | C1: Variable Continua | E1: n | F1: =COUNT('Estadísticos Descriptivos'!A2:A890) -> 889 | AI1: Tarifa | AK1: Variable Continua | AM1: n | AN1: =COUNT('Estadísticos Descriptivos'!AI2:AI890) -> 889 | BP1: Hermanos/Conyuges | BS1: Variable Númerica Discreta
A2: 0.42 | E2: Rango | F2: =MAX('Estadísticos Descriptivos'!A2:A890) - MIN('Estadísticos Descriptivos'!A2:A890) -> 79.58 | I2: EDAD | AI2: 0 | AM2: Rango | AN2: =MAX('Estadísticos Descriptivos'!AI2:AI890 ) - MIN('Estadísticos Descriptivos'!AI2:AI890) -> 512.3292 | AQ2: TARIFA | BP2: 0 | BS2: e) Distribución de Frecuencias de Familiares a bordo en el Titanic | CD2: FAMILIARES
A3: 0.67 | E3: K | F3: =ROUND(1 + 3.32*LOG(F1), 0) -> 11 | AI3: 0 | AM3: K | AN3: =ROUND(1 + 3.32*LOG(AN1), 0) -> 11 | BP3: 0 | BX3: F.acum. Menor que | CA3: F.acum Mayor que
A4: 0.75 | E4: W | F4: =ROUND(F2/F3, 0) -> 7 | AI4: 0 | AM4: W | AN4: =ROUND(AN2/AN3,0) -> 47 | BP4: 0 | BS4: Categoría | BT4: Valor | BU4: fi | BV4: fr | BW4: % | BX4: Fi(-) | BY4: Fr(-) | BZ4: %(-) | CA4: Fi(+) | CB4: Fr(+) | CC4: %(+)
A5: 0.75 | C5: POR FAVOR IR MAS A LA DERECHA PARA VER LAS OTRAS 3 VARIABLES | AI5: 0 | BP5: 0 | BS5: Sin familiares a bordo | BT5: 0 | BU5: {=FREQUENCY('Estadísticos Descriptivos'!BP2:BP890, BT5:BT11)} -> 606 | BV5: =BU5/$BU$12 -> 0.68166479 | BW5: =BV5 -> 0.68166479 | BX5: =BU5 -> 606 | BY5: =BV5 -> 0.68166479 | BZ5: =BW5 -> 0.68166479 | CA5: {=BU12:BW12} -> 889 | CB5: 1 | CC5: 1
A6: 0.83 | C6: a) Distribución de Frecuencias por Edad de Pasajeros del Titanic | AI6: 0 | AK6: b) Distribución de Frecuencias por Tarifa de Pasajeros del Titanic | BP6: 0 | BS6: 1 familiar | BT6: 1 | BU6: 209 | BV6: =BU6/$BU$12 -> 0.23509561 | BW6: =BV6 -> 0.23509561 | BX6: =BX5+BU6 -> 815 | BY6: =BY5+BV6 -> 0.9167604 | BZ6: =BZ5+BW6 -> 0.9167604 | CA6: {=CA5:CC5-BU5:BW5} -> 283 | CB6: 0.31833521 | CC6: 0.31833521
A7: 0.83 | I7: F.acum. Menor que | L7: F.acum Mayor que | AI7: 0 | BP7: 0 | BS7: 2 familiares | BT7: 2 | BU7: 28 | BV7: =BU7/$BU$12 -> 0.031496063 | BW7: =BV7 -> 0.031496063 | BX7: =BX6+BU7 -> 843 | BY7: =BY6+BV7 -> 0.94825647 | BZ7: =BZ6+BW7 -> 0.94825647 | CA7: {=CA6:CC6-BU6:BW6} -> 74 | CB7: 0.083239595 | CC7: 0.083239595
A8: 0.92 | C8: Intervalos | E8: Intervalos | F8: fi | G8: fr | H8: % | I8: Fi (-) | J8: Fr(-) | K8: % (-) | L8: Fi (+) | M8: Fr(+) | N8: % (+) | O8: PM (Xi) | AI8: 0 | AK8: Intervalos | AM8: Intervalos | AN8: fi | AO8: fr | AP8: % | AQ8: Fi (-) | AR8: Fr(-) | AS8: % (-) | AT8: Fi (+) | AU8: Fr(+) | AV8: % (+) | AW8: PM (Xi) | BP8: 0 | BS8: 3 familiares | BT8: 3 | BU8: 16 | BV8: =BU8/$BU$12 -> 0.01799775 | BW8: =BV8 -> 0.01799775 | BX8: =BX7+BU8 -> 859 | BY8: =BY7+BV8 -> 0.96625422 | BZ8: =BZ7+BW8 -> 0.96625422 | CA8: {=CA7:CC7-BU7:BW7} -> 46 | CB8: 0.051743532 | CC8: 0.051743532
A9: 1 | C9: =MIN('Estadísticos Descriptivos'!A2:A890) -> 0.42 | D9: =C10-1 -> 6.42 | E9: =TEXT(C9, "0") & " - " & TEXT(D9, "0") -> 0 - 6 | F9: {=FREQUENCY('Estadísticos Descriptivos'!A2:A890, D9:D20)} -> 47 | G9: =F9/$F$21 -> 0.052868391 | H9: =G9 -> 0.052868391 | I9: =F9 -> 47 | J9: =G9 -> 0.052868391 | K9: =H9 -> 0.052868391 | L9: =F21 -> 889 | M9: =G21 -> 1 | N9: =H21 -> 1 | O9: =AVERAGE(C9:D9) -> 3.42 | AI9: 0 | AK9: =MIN('Estadísticos Descriptivos'!AI2:AI890) -> 0 | AL9: =AK10-1 -> 46 | AM9: =TEXT(AK9, "0") & " - " & TEXT(AL9, "0") -> 0 - 46 | AN9: {=FREQUENCY('Estadísticos Descriptivos'!AI2:AI890, AL9:AL19)} -> 720 | AO9: =AN9/'Estadísticos Descriptivos'!$F$21 -> 0.80989876 | AP9: =AO9 -> 0.80989876 | AQ9: =AN9 -> 720 | AR9: =AO9 -> 0.80989876 | AS9: =AP9 -> 0.80989876 | AT9: =AN20 -> 889 | AU9: =AO20 -> 1 | AV9: =AP20 -> 1 | AW9: =AVERAGE(AK9:AL9) -> 23 | BP9: 0 | BS9: 4 familiares | BT9: 4 | BU9: 18 | BV9: =BU9/$BU$12 -> 0.020247469 | BW9: =BV9 -> 0.020247469 | BX9: =BX8+BU9 -> 877 | BY9: =BY8+BV9 -> 0.98650169 | BZ9: =BZ8+BW9 -> 0.98650169 | CA9: {=CA8:CC8-BU8:BW8} -> 30 | CB9: 0.033745782 | CC9: 0.033745782
A10: 1 | C10: =C9+$F$4 -> 7.42 | D10: =D9+$F$4 -> 13.42 | E10: =TEXT(C10, "0") & " - " & TEXT(D10, "0") -> 7 - 13 | F10: 24 | G10: =F10/$F$21 -> 0.026996625 | H10: =G10 -> 0.026996625 | I10: =I9+F10 -> 71 | J10: =J9+G10 -> 0.079865017 | K10: =K9+H10 -> 0.079865017 | L10: =L9-F9 -> 842 | M10: =M9-G9 -> 0.94713161 | N10: =N9-H9 -> 0.94713161 | O10: =AVERAGE(C10:D10) -> 10.42 | AI10: 0 | AK10: =AK9+$AN$4 -> 47 | AL10: =AL9+$AN$4 -> 93 | AM10: =TEXT(AK10, "0") & " - " & TEXT(AL10, "0") -> 47 - 93 | AN10: 114 | AO10: =AN10/'Estadísticos Descriptivos'!$F$21 -> 0.12823397 | AP10: =AO10 -> 0.12823397 | AQ10: =AQ9+AN10 -> 834 | AR10: =AR9+AO10 -> 0.93813273 | AS10: =AS9+AP10 -> 0.93813273 | AT10: =AT9-AN9 -> 169 | AU10: =AU9-AO9 -> 0.19010124 | AV10: =AV9-AP9 -> 0.19010124 | AW10: =AVERAGE(AK10:AL10) -> 70 | BP10: 0 | BS10: 5 familiares | BT10: 5 | BU10: 5 | BV10: =BU10/$BU$12 -> 0.005624297 | BW10: =BV10 -> 0.005624297 | BX10: =BX9+BU10 -> 882 | BY10: =BY9+BV10 -> 0.99212598 | BZ10: =BZ9+BW10 -> 0.99212598 | CA10: {=CA9:CC9-BU9:BW9} -> 12 | CB10: 0.013498313 | CC10: 0.013498313
A11: 1 | C11: =C10+$F$4 -> 14.42 | D11: =D10+$F$4 -> 20.42 | E11: =TEXT(C11, "0") & " - " & TEXT(D11, "0") -> 14 - 20 | F11: 108 | G11: =F11/$F$21 -> 0.12148481 | H11: =G11 -> 0.12148481 | I11: =I10+F11 -> 179 | J11: =J10+G11 -> 0.20134983 | K11: =K10+H11 -> 0.20134983 | L11: =L10-F10 -> 818 | M11: =M10-G10 -> 0.92013498 | N11: =N10-H10 -> 0.92013498 | O11: =AVERAGE(C11:D11) -> 17.42 | AI11: 0 | AK11: =AK10+$AN$4 -> 94 | AL11: =AL10+$AN$4 -> 140 | AM11: =TEXT(AK11, "0") & " - " & TEXT(AL11, "0") -> 94 - 140 | AN11: 24 | AO11: =AN11/'Estadísticos Descriptivos'!$F$21 -> 0.026996625 | AP11: =AO11 -> 0.026996625 | AQ11: =AQ10+AN11 -> 858 | AR11: =AR10+AO11 -> 0.96512936 | AS11: =AS10+AP11 -> 0.96512936 | AT11: =AT10-AN10 -> 55 | AU11: =AU10-AO10 -> 0.061867267 | AV11: =AV10-AP10 -> 0.061867267 | AW11: =AVERAGE(AK11:AL11) -> 117 | BP11: 0 | BS11: 8 familiares | BT11: 8 | BU11: 7 | BV11: =BU11/$BU$12 -> 0.0078740157 | BW11: =BV11 -> 0.0078740157 | BX11: =BX10+BU11 -> 889 | BY11: =BY10+BV11 -> 1 | BZ11: =BZ10+BW11 -> 1 | CA11: {=CA10:CC10-BU10:BW10} -> 7 | CB11: 0.0078740157 | CC11: 0.0078740157
A12: 1 | C12: =C11+$F$4 -> 21.42 | D12: =D11+$F$4 -> 27.42 | E12: =TEXT(C12, "0") & " - " & TEXT(D12, "0") -> 21 - 27 | F12: 158 | G12: =F12/$F$21 -> 0.17772778 | H12: =G12 -> 0.17772778 | I12: =I11+F12 -> 337 | J12: =J11+G12 -> 0.37907762 | K12: =K11+H12 -> 0.37907762 | L12: =L11-F11 -> 710 | M12: =M11-G11 -> 0.79865017 | N12: =N11-H11 -> 0.79865017 | O12: =AVERAGE(C12:D12) -> 24.42 | AI12: 0 | AK12: =AK11+$AN$4 -> 141 | AL12: =AL11+$AN$4 -> 187 | AM12: =TEXT(AK12, "0") & " - " & TEXT(AL12, "0") -> 141 - 187 | AN12: 11 | AO12: =AN12/'Estadísticos Descriptivos'!$F$21 -> 0.012373453 | AP12: =AO12 -> 0.012373453 | AQ12: =AQ11+AN12 -> 869 | AR12: =AR11+AO12 -> 0.97750281 | AS12: =AS11+AP12 -> 0.97750281 | AT12: =AT11-AN11 -> 31 | AU12: =AU11-AO11 -> 0.034870641 | AV12: =AV11-AP11 -> 0.034870641 | AW12: =AVERAGE(AK12:AL12) -> 164 | BP12: 0 | BS12: Total | BU12: =SUM(BU5:BU11) -> 889 | BV12: =SUM(BV5:BV11) -> 1 | BW12: =SUM(BW5:BW11) -> 1
A13: 1 | C13: =C12+$F$4 -> 28.42 | D13: =D12+$F$4 -> 34.42 | E13: =TEXT(C13, "0") & " - " & TEXT(D13, "0") -> 28 - 34 | F13: 318 | G13: =F13/$F$21 -> 0.35770529 | H13: =G13 -> 0.35770529 | I13: =I12+F13 -> 655 | J13: =J12+G13 -> 0.7367829 | K13: =K12+H13 -> 0.7367829 | L13: =L12-F12 -> 552 | M13: =M12-G12 -> 0.62092238 | N13: =N12-H12 -> 0.62092238 | O13: =AVERAGE(C13:D13) -> 31.42 | AI13: 0 | AK13: =AK12+$AN$4 -> 188 | AL13: =AL12+$AN$4 -> 234 | AM13: =TEXT(AK13, "0") & " - " & TEXT(AL13, "0") -> 188 - 234 | AN13: 9 | AO13: =AN13/'Estadísticos Descriptivos'!$F$21 -> 0.010123735 | AP13: =AO13 -> 0.010123735 | AQ13: =AQ12+AN13 -> 878 | AR13: =AR12+AO13 -> 0.98762655 | AS13: =AS12+AP13 -> 0.98762655 | AT13: =AT12-AN12 -> 20 | AU13: =AU12-AO12 -> 0.022497188 | AV13: =AV12-AP12 -> 0.022497188 | AW13: =AVERAGE(AK13:AL13) -> 211 | BP13: 0
A14: 1 | C14: =C13+$F$4 -> 35.42 | D14: =D13+$F$4 -> 41.42 | E14: =TEXT(C14, "0") & " - " & TEXT(D14, "0") -> 35 - 41 | F14: 93 | G14: =F14/$F$21 -> 0.10461192 | H14: =G14 -> 0.10461192 | I14: =I13+F14 -> 748 | J14: =J13+G14 -> 0.84139483 | K14: =K13+H14 -> 0.84139483 | L14: =L13-F13 -> 234 | M14: =M13-G13 -> 0.2632171 | N14: =N13-H13 -> 0.2632171 | O14: =AVERAGE(C14:D14) -> 38.42 | AI14: 0 | AK14: =AK13+$AN$4 -> 235 | AL14: =AL13+$AN$4 -> 281 | AM14: =TEXT(AK14, "0") & " - " & TEXT(AL14, "0") -> 235 - 281 | AN14: 8 | AO14: =AN14/'Estadísticos Descriptivos'!$F$21 -> 0.0089988751 | AP14: =AO14 -> 0.0089988751 | AQ14: =AQ13+AN14 -> 886 | AR14: =AR13+AO14 -> 0.99662542 | AS14: =AS13+AP14 -> 0.99662542 | AT14: =AT13-AN13 -> 11 | AU14: =AU13-AO13 -> 0.012373453 | AV14: =AV13-AP13 -> 0.012373453 | AW14: =AVERAGE(AK14:AL14) -> 258 | BP14: 0 | BS14: INTERPRETACION
A15: 1 | C15: =C14+$F$4 -> 42.42 | D15: =D14+$F$4 -> 48.42 | E15: =TEXT(C15, "0") & " - " & TEXT(D15, "0") -> 42 - 48 | F15: 62 | G15: =F15/$F$21 -> 0.069741282 | H15: =G15 -> 0.069741282 | I15: =I14+F15 -> 810 | J15: =J14+G15 -> 0.91113611 | K15: =K14+H15 -> 0.91113611 | L15: =L14-F14 -> 141 | M15: =M14-G14 -> 0.15860517 | N15: =N14-H14 -> 0.15860517 | O15: =AVERAGE(C15:D15) -> 45.42 | AI15: 0 | AK15: =AK14+$AN$4 -> 282 | AL15: =AL14+$AN$4 -> 328 | AM15: =TEXT(AK15, "0") & " - " & TEXT(AL15, "0") -> 282 - 328 | AN15: 0 | AO15: =AN15/'Estadísticos Descriptivos'!$F$21 -> 0 | AP15: =AO15 -> 0 | AQ15: =AQ14+AN15 -> 886 | AR15: =AR14+AO15 -> 0.99662542 | AS15: =AS14+AP15 -> 0.99662542 | AT15: =AT14-AN14 -> 3 | AU15: =AU14-AO14 -> 0.0033745782 | AV15: =AV14-AP14 -> 0.0033745782 | AW15: =AVERAGE(AK15:AL15) -> 305 | BP15: 0 | BS15: Los datos revelan que la mayoría absoluta (68%) de los pasajeros viajaba solo, sin familiares a bordo, lo cual refleja patrones migratorios y laborales de 1912.
A16: 2 | C16: =C15+$F$4 -> 49.42 | D16: =D15+$F$4 -> 55.42 | E16: =TEXT(C16, "0") & " - " & TEXT(D16, "0") -> 49 - 55 | F16: 40 | G16: =F16/$F$21 -> 0.044994376 | H16: =G16 -> 0.044994376 | I16: =I15+F16 -> 850 | J16: =J15+G16 -> 0.95613048 | K16: =K15+H16 -> 0.95613048 | L16: =L15-F15 -> 79 | M16: =M15-G15 -> 0.088863892 | N16: =N15-H15 -> 0.088863892 | O16: =AVERAGE(C16:D16) -> 52.42 | AI16: 0 | AK16: =AK15+$AN$4 -> 329 | AL16: =AL15+$AN$4 -> 375 | AM16: =TEXT(AK16, "0") & " - " & TEXT(AL16, "0") -> 329 - 375 | AN16: 0 | AO16: =AN16/'Estadísticos Descriptivos'!$F$21 -> 0 | AP16: =AO16 -> 0 | AQ16: =AQ15+AN16 -> 886 | AR16: =AR15+AO16 -> 0.99662542 | AS16: =AS15+AP16 -> 0.99662542 | AT16: =AT15-AN15 -> 3 | AU16: =AU15-AO15 -> 0.0033745782 | AV16: =AV15-AP15 -> 0.0033745782 | AW16: =AVERAGE(AK16:AL16) -> 352 | BP16: 0 | BS16: Solo el 24% tenía 1 familiar, y el 8% restante (solo 74 personas) tenía 2 o más parientes.
A17: 2 | C17: =C16+$F$4 -> 56.42 | D17: =D16+$F$4 -> 62.42 | E17: =TEXT(C17, "0") & " - " & TEXT(D17, "0") -> 56 - 62 | F17: 24 | G17: =F17/$F$21 -> 0.026996625 | H17: =G17 -> 0.026996625 | I17: =I16+F17 -> 874 | J17: =J16+G17 -> 0.98312711 | K17: =K16+H17 -> 0.98312711 | L17: =L16-F16 -> 39 | M17: =M16-G16 -> 0.043869516 | N17: =N16-H16 -> 0.043869516 | O17: =AVERAGE(C17:D17) -> 59.42 | AI17: 4.0125 | AK17: =AK16+$AN$4 -> 376 | AL17: =AL16+$AN$4 -> 422 | AM17: =TEXT(AK17, "0") & " - " & TEXT(AL17, "0") -> 376 - 422 | AN17: 0 | AO17: =AN17/'Estadísticos Descriptivos'!$F$21 -> 0 | AP17: =AO17 -> 0 | AQ17: =AQ16+AN17 -> 886 | AR17: =AR16+AO17 -> 0.99662542 | AS17: =AS16+AP17 -> 0.99662542 | AT17: =AT16-AN16 -> 3 | AU17: =AU16-AO16 -> 0.0033745782 | AV17: =AV16-AP16 -> 0.0033745782 | AW17: =AVERAGE(AK17:AL17) -> 399 | BP17: 0 | BS17: Los casos extremos de 4, 5 y 8 familiares son anomalías estadísticas (<1% cada uno), posiblemente familias numerosas migrando juntas.
A18: 2 | C18: =C17+$F$4 -> 63.42 | D18: =D17+$F$4 -> 69.42 | E18: =TEXT(C18, "0") & " - " & TEXT(D18, "0") -> 63 - 69 | F18: 8 | G18: =F18/$F$21 -> 0.0089988751 | H18: =G18 -> 0.0089988751 | I18: =I17+F18 -> 882 | J18: =J17+G18 -> 0.99212598 | K18: =K17+H18 -> 0.99212598 | L18: =L17-F17 -> 15 | M18: =M17-G17 -> 0.016872891 | N18: =N17-H17 -> 0.016872891 | O18: =AVERAGE(C18:D18) -> 66.42 | AI18: 5 | AK18: =AK17+$AN$4 -> 423 | AL18: =AL17+$AN$4 -> 469 | AM18: =TEXT(AK18, "0") & " - " & TEXT(AL18, "0") -> 423 - 469 | AN18: 0 | AO18: =AN18/'Estadísticos Descriptivos'!$F$21 -> 0 | AP18: =AO18 -> 0 | AQ18: =AQ17+AN18 -> 886 | AR18: =AR17+AO18 -> 0.99662542 | AS18: =AS17+AP18 -> 0.99662542 | AT18: =AT17-AN17 -> 3 | AU18: =AU17-AO17 -> 0.0033745782 | AV18: =AV17-AP17 -> 0.0033745782 | AW18: =AVERAGE(AK18:AL18) -> 446 | BP18: 0 | BS18: Outliers: El valor 8 familiares es atípico y debe analizarse como caso especial
A19: 2 | C19: =C18+$F$4 -> 70.42 | D19: =D18+$F$4 -> 76.42 | E19: =TEXT(C19, "0") & " - " & TEXT(D19, "0") -> 70 - 76 | F19: 6 | G19: =F19/$F$21 -> 0.0067491564 | H19: =G19 -> 0.0067491564 | I19: =I18+F19 -> 888 | J19: =J18+G19 -> 0.99887514 | K19: =K18+H19 -> 0.99887514 | L19: =L18-F18 -> 7 | M19: =M18-G18 -> 0.0078740157 | N19: =N18-H18 -> 0.0078740157 | O19: =AVERAGE(C19:D19) -> 73.42 | AI19: 6.2375 | AK19: =AK18+$AN$4 -> 470 | AL19: =AL18+$AN$4 -> 516 | AM19: =TEXT(AK19, "0") & " - " & TEXT(AL19, "0") -> 470 - 516 | AN19: 3 | AO19: =AN19/'Estadísticos Descriptivos'!$F$21 -> 0.0033745782 | AP19: =AO19 -> 0.0033745782 | AQ19: =AQ18+AN19 -> 889 | AR19: =AR18+AO19 -> 1 | AS19: =AS18+AP19 -> 1 | AT19: =AT18-AN18 -> 3 | AU19: =AU18-AO18 -> 0.0033745782 | AV19: =AV18-AP18 -> 0.0033745782 | AW19: =AVERAGE(AK19:AL19) -> 493 | BP19: 0
A20: 2 | C20: =C19+$F$4 -> 77.42 | D20: =D19+$F$4 -> 83.42 | E20: =TEXT(C20, "0") & " - " & TEXT(D20, "0") -> 77 - 83 | F20: 1 | G20: =F20/$F$21 -> 0.0011248594 | H20: =G20 -> 0.0011248594 | I20: =I19+F20 -> 889 | J20: =J19+G20 -> 1 | K20: =K19+H20 -> 1 | L20: =L19-F19 -> 1 | M20: =M19-G19 -> 0.0011248594 | N20: =N19-H19 -> 0.0011248594 | O20: =AVERAGE(C20:D20) -> 80.42 | AI20: 6.4375 | AK20: Total | AN20: =SUM(AN9:AN19) -> 889 | AO20: =SUM(AO9:AO19) -> 1 | AP20: =AO20 -> 1 | BP20: 0 | BR20: REPRESENTACION VISUAL | CA20: REPRESENTACION VISUAL
A21: 2 | F21: =SUM(F9:F20) -> 889 | G21: =SUM(G9:G20) -> 1 | H21: =SUM(H9:H20) -> 1 | AI21: 6.45 | BP21: 0 | BR21: Torta o gráfico circular | CA21: Histograma o gráfico de barras
A22: 2 | AI22: 6.4958 | AK22: INTERPRETACION | BP22: 0 | BR22: Grafico N°1 Distribución de pasajeros según número de familiares a bordo | CA22: Grafico N°2 Distribución de pasajeros según número de familiares a bordo
A23: 2 | C23: INTERPRETACION | AI23: 6.4958 | AK23: La distribución de tarifas muestra una concentración extrema en el rango bajo | BP23: 0
A24: 2 | C24: La distribución etaria muestra una concentración marcada en adultos jóvenes | AI24: 6.75 | AK24: El 81% de pasajeros pagó entre £0-46, mientras que solo el 19% restante abonó tarifas superiores. | BP24: 0
A25: 2 | C25: El 36% de pasajeros tenía entre 28-34 años (318 personas), y sumando el rango 21-27 años (18%), más de la mitad (54%) estaba entre los 21 y 34 años. | AI25: 6.75 | AK25: Los intervalos entre £282-422 están completamente vacíos, evidenciando una brecha estructural entre clases. | BP25: 0
A26: 3 | C26: Los niños pequeños (0-6 años) representan solo el 5%, mientras que adultos mayores de 63 años apenas suman el 2%. | AI26: 6.8583 | AK26: Las tarifas más altas (£470-516) representan solo 3 casos (0.3%), correspondientes a suites de primera clase de lujo. | BP26: 0
A27: 3 | C27: Pico poblacional: 28-34 años (probablemente trabajadores migrantes) | AI27: 6.95 | AK27: Estratificación social: Los intervalos vacíos reflejan la ausencia de "clase media" en 1912 | BP27: 0
A28: 3 | AI28: 6.975 | BP28: 0
A29: 3 | C29: REPRESENTACION VISUAL | M29: REPRESENTACION VISUAL | X29: REPRESENTACION VISUAL | AI29: 6.975 | AK29: REPRESENTACION VISUAL | AU29: REPRESENTACION VISUAL | BE29: REPRESENTACION VISUAL | BP29: 0
A30: 3 | C30: Histograma o gráfico de barras | M30: Torta o gráfica circulas | X30: Torta o gráfica circulas | AI30: 7.0458 | AK30: Histograma o gráfico de barras | AU30: Torta o gráfica circulas | BE30: Torta o gráfica circulas | BP30: 0
A31: 3 | C31: Grafico N°1 Distribución de frecuencias absolutas por intervalos de edad | M31: Grafico N°3 tiempo de ensamble de un chasis | X31: Grafico N°5 Porcentaje acumulativo de pasajeros por edad decreciente | AI31: 7.05 | AK31: Grafico N°1 Distribución de frecuencias de tarifas del pasaje del Titanic | AU31: Grafico N°3 Distribución de frecuencias de tarifas del pasaje del Titanic | BE31: Grafico N°5 Distribución de frecuencias de tarifas del pasaje del Titanic | BP31: 0
A32: 4 | AI32: 7.05 | BP32: 0
A33: 4 | AI33: 7.05 | BP33: 0
A34: 4 | AI34: 7.05 | BP34: 0
A35: 4 | AI35: 7.05 | BP35: 0 | BR35: Fuente: Dataset público de Kaggle "Titanic - Machine Learning from Disaster" | CA35: Fuente: Dataset público de Kaggle "Titanic - Machine Learning from Disaster"
A36: 4 | AI36: 7.05 | BP36: 0
A37: 4 | AI37: 7.05 | BP37: 0
A38: 4 | AI38: 7.0542 | BP38: 0 | BR38: DATOS SIN AGRUPAR | CF38: DATOS AGRUPADOS
A39: 4 | AI39: 7.0542 | BP39: 0 | BR39: Medidas de tendencia Central | CF39: La variable HermanosConyuges es de tipo cuantitativa discreta con rango limitado (valores únicos: 0, 1, 2, 3, 4, 5, 6, 8) y frecuencia predominante en el valor cero (67% de casos).
A40: 4 | AI40: 7.125 | BP40: 0 | BR40: Media o promedio | CF40: Dado su carácter discreto y la escasa dispersión de valores, no es estadísticamente apropiado agruparla en intervalos de clase.
...
